[2023-09-11T05:28:06.666+0000] {taskinstance.py:1159} INFO - Dependencies all met for dep_context=non-requeueable deps ti=<TaskInstance: test01.test02 manual__2023-09-11T05:27:35.035012+00:00 [queued]>
[2023-09-11T05:28:06.671+0000] {taskinstance.py:1159} INFO - Dependencies all met for dep_context=requeueable deps ti=<TaskInstance: test01.test02 manual__2023-09-11T05:27:35.035012+00:00 [queued]>
[2023-09-11T05:28:06.671+0000] {taskinstance.py:1361} INFO - Starting attempt 1 of 1
[2023-09-11T05:28:06.678+0000] {taskinstance.py:1382} INFO - Executing <Task(PythonOperator): test02> on 2023-09-11 05:27:35.035012+00:00
[2023-09-11T05:28:06.682+0000] {standard_task_runner.py:57} INFO - Started process 609 to run task
[2023-09-11T05:28:06.686+0000] {standard_task_runner.py:84} INFO - Running: ['***', 'tasks', 'run', 'test01', 'test02', 'manual__2023-09-11T05:27:35.035012+00:00', '--job-id', '66', '--raw', '--subdir', 'DAGS_FOLDER/Orders_realPaidPrice.py', '--cfg-path', '/tmp/tmp8ttn6nei']
[2023-09-11T05:28:06.687+0000] {standard_task_runner.py:85} INFO - Job 66: Subtask test02
[2023-09-11T05:28:06.723+0000] {task_command.py:415} INFO - Running <TaskInstance: test01.test02 manual__2023-09-11T05:27:35.035012+00:00 [running]> on host 4b74fbf5f024
[2023-09-11T05:28:06.777+0000] {taskinstance.py:1660} INFO - Exporting env vars: AIRFLOW_CTX_DAG_OWNER='***' AIRFLOW_CTX_DAG_ID='test01' AIRFLOW_CTX_TASK_ID='test02' AIRFLOW_CTX_EXECUTION_DATE='2023-09-11T05:27:35.035012+00:00' AIRFLOW_CTX_TRY_NUMBER='1' AIRFLOW_CTX_DAG_RUN_ID='manual__2023-09-11T05:27:35.035012+00:00'
[2023-09-11T05:28:08.872+0000] {taskinstance.py:1943} ERROR - Task failed with exception
Traceback (most recent call last):
  File "/home/airflow/.local/lib/python3.8/site-packages/airflow/operators/python.py", line 192, in execute
    return_value = self.execute_callable()
  File "/home/airflow/.local/lib/python3.8/site-packages/airflow/operators/python.py", line 209, in execute_callable
    return self.python_callable(*self.op_args, **self.op_kwargs)
  File "/opt/airflow/plugins/read/ReadS3Orders.py", line 29, in ReadS3OrdersData
    obj = s3.get_object(Bucket=bucket, Key= f"practice/{2023}-{9}-{10}-{5}.csv")
  File "/home/airflow/.local/lib/python3.8/site-packages/botocore/client.py", line 535, in _api_call
    return self._make_api_call(operation_name, kwargs)
  File "/home/airflow/.local/lib/python3.8/site-packages/botocore/client.py", line 963, in _make_api_call
    http, parsed_response = self._make_request(
  File "/home/airflow/.local/lib/python3.8/site-packages/botocore/client.py", line 986, in _make_request
    return self._endpoint.make_request(operation_model, request_dict)
  File "/home/airflow/.local/lib/python3.8/site-packages/botocore/endpoint.py", line 119, in make_request
    return self._send_request(request_dict, operation_model)
  File "/home/airflow/.local/lib/python3.8/site-packages/botocore/endpoint.py", line 198, in _send_request
    request = self.create_request(request_dict, operation_model)
  File "/home/airflow/.local/lib/python3.8/site-packages/botocore/endpoint.py", line 134, in create_request
    self._event_emitter.emit(
  File "/home/airflow/.local/lib/python3.8/site-packages/botocore/hooks.py", line 412, in emit
    return self._emitter.emit(aliased_event_name, **kwargs)
  File "/home/airflow/.local/lib/python3.8/site-packages/botocore/hooks.py", line 256, in emit
    return self._emit(event_name, kwargs)
  File "/home/airflow/.local/lib/python3.8/site-packages/botocore/hooks.py", line 239, in _emit
    response = handler(**kwargs)
  File "/home/airflow/.local/lib/python3.8/site-packages/botocore/signers.py", line 105, in handler
    return self.sign(operation_name, request)
  File "/home/airflow/.local/lib/python3.8/site-packages/botocore/signers.py", line 189, in sign
    auth.add_auth(request)
  File "/home/airflow/.local/lib/python3.8/site-packages/botocore/auth.py", line 418, in add_auth
    raise NoCredentialsError()
botocore.exceptions.NoCredentialsError: Unable to locate credentials
[2023-09-11T05:28:08.881+0000] {taskinstance.py:1400} INFO - Marking task as FAILED. dag_id=test01, task_id=test02, execution_date=20230911T052735, start_date=20230911T052806, end_date=20230911T052808
[2023-09-11T05:28:08.889+0000] {standard_task_runner.py:104} ERROR - Failed to execute job 66 for task test02 (Unable to locate credentials; 609)
[2023-09-11T05:28:08.923+0000] {local_task_job_runner.py:228} INFO - Task exited with return code 1
[2023-09-11T05:28:08.940+0000] {taskinstance.py:2784} INFO - 0 downstream tasks scheduled from follow-on schedule check
